2019-01-29 10:39:38,513 - INFO - Order #5
2019-01-29 10:39:38,513 - INFO - ==========
2019-01-29 10:39:38,520 - INFO - 

2019-01-29 10:39:38,526 - INFO - Sub-iteration #1
2019-01-29 10:39:38,526 - INFO - ================
2019-01-29 10:39:40,053 - INFO - Adding columns to gPC matrix...
2019-01-29 10:39:40,068 - INFO - Adding rows to gPC matrix...
2019-01-29 10:39:40,371 - INFO - Performing simulations 1583 to 1602
It/Sub-it: 5/1 Performing simulation 20 from 20 [========================================] 100%
2019-01-29 10:39:46,543 - INFO - Total parallel function evaluation: 6.17247891426 sec
LOOCV 100 from 100 [========================================] 100%
2019-01-29 10:42:18,959 - INFO - LOOCV computation time: 147.897403955 sec
2019-01-29 10:42:18,959 - INFO - -> error = 0.0130113676617
2019-01-29 10:42:18,959 - INFO - 

2019-01-29 10:42:18,960 - INFO - Sub-iteration #2
2019-01-29 10:42:18,960 - INFO - ================
2019-01-29 10:42:21,686 - INFO - Adding columns to gPC matrix...
2019-01-29 10:42:21,998 - INFO - Adding rows to gPC matrix...
2019-01-29 10:42:22,469 - INFO - Performing simulations 1603 to 1962
It/Sub-it: 5/2 Performing simulation 360 from 360 [========================================] 100%
2019-01-29 10:43:41,581 - INFO - Total parallel function evaluation: 79.111353159 sec
LOOCV 100 from 100 [========================================] 100%
2019-01-29 10:47:41,934 - INFO - LOOCV computation time: 234.884585857 sec
2019-01-29 10:47:41,935 - INFO - -> error = 0.0116745996517
2019-01-29 10:47:41,935 - INFO - 

2019-01-29 10:47:41,935 - INFO - Sub-iteration #3
2019-01-29 10:47:41,935 - INFO - ================
2019-01-29 10:47:49,142 - INFO - Adding columns to gPC matrix...
2019-01-29 10:47:50,984 - INFO - Adding rows to gPC matrix...
2019-01-29 10:47:52,344 - INFO - Performing simulations 1963 to 3402
[ simnibs ]CRITICAL: Unhandled excemption:
Traceback (most recent call last):
  File "/data/pt_01756/software/git/scripts/gpc/c/run_c_gpc.py", line 123, in <module>
    ###################################################################################
  File "/data/pt_01756/software/git/pygpc/pygpc/Algorithm.py", line 400, in run
    i_iter=order,
  File "/data/pt_01756/software/git/pygpc/pygpc/Computation.py", line 128, in run
    res_new_list = self.process_pool.map(Worker.run, worker_objs)
  File "/usr/lib/python2.7/multiprocessing/pool.py", line 251, in map
    return self.map_async(func, iterable, chunksize).get()
  File "/usr/lib/python2.7/multiprocessing/pool.py", line 567, in get
    raise self._value
IOError: bad message length
Traceback (most recent call last):
  File "/data/pt_01756/software/git/scripts/gpc/c/run_c_gpc.py", line 123, in <module>
    ###################################################################################
  File "/data/pt_01756/software/git/pygpc/pygpc/Algorithm.py", line 400, in run
    i_iter=order,
  File "/data/pt_01756/software/git/pygpc/pygpc/Computation.py", line 128, in run
    res_new_list = self.process_pool.map(Worker.run, worker_objs)
  File "/usr/lib/python2.7/multiprocessing/pool.py", line 251, in map
    return self.map_async(func, iterable, chunksize).get()
  File "/usr/lib/python2.7/multiprocessing/pool.py", line 567, in get
    raise self._value
IOError: bad message length
kweise@ufo:~ > 

